Workbook

Sheet Data Set
A1: Gender | B1: Race/Rthnicity | C1: Parental Level of Education | D1: Lunch | E1: Test Preparation Course | F1: StudyTimeWeekly | G1: Absences | H1: Math Score | I1: Reading Score | J1: Writing Score | K1: Overall Academic Score
A2: female | B2: group B | C2: bachelor's degree | D2: standard | E2: none | F2: 11.36638302155851 | G2: 26 | H2: 72 | I2: 72 | J2: 74 | K2: =(H2+I2)/2 -> 72
A3: female | B3: group C | C3: some college | D3: standard | E3: completed | F3: 3.761171329581512 | G3: 13 | H3: 69 | I3: 90 | J3: 88 | K3: =(H3+I3)/2 -> 79.5 | N3: t - test | O3: =_xlfn.T.TEST(H2:H1001,I2:I1001,2,2) -> 3.9464455e-06 | Q3: =_xlfn.T.TEST(H2:H1001,I2:I1001,1,1) -> 3.661168e-26
A4: female | B4: group B | C4: master's degree | D4: standard | E4: none | F4: 5.370001523949908 | G4: 22 | H4: 90 | I4: 95 | J4: 93 | K4: =(H4+I4)/2 -> 92.5
A5: male | B5: group A | C5: associate's degree | D5: free/reduced | E5: none | F5: 5.497913165141755 | G5: 21 | H5: 47 | I5: 57 | J5: 44 | K5: =(H5+I5)/2 -> 52 | N5: One-Sample t-test
A6: male | B6: group C | C6: some college | D6: standard | E6: none | F6: 7.859015299827061 | G6: 19 | H6: 76 | I6: 78 | J6: 75 | K6: =(H6+I6)/2 -> 77 | N6: Avg. Overall Academic Score | O6: =AVERAGE(K2:K1001) -> 67.629
A7: female | B7: group B | C7: associate's degree | D7: standard | E7: none | F7: 13.896414597434415 | G7: 11 | H7: 71 | I7: 83 | J7: 78 | K7: =(H7+I7)/2 -> 77 | N7: STD. Overall Academic Score | O7: =_xlfn.STDEV.S(K2:K1001) -> 14.186988
A8: female | B8: group B | C8: some college | D8: standard | E8: completed | F8: 2.912574770509029 | G8: 25 | H8: 88 | I8: 95 | J8: 92 | K8: =(H8+I8)/2 -> 91.5 | N8: Sample Size | O8: =COUNT(K2:K1001) -> 1000
A9: male | B9: group B | C9: some college | D9: free/reduced | E9: none | F9: 2.4692714746147204 | G9: 19 | H9: 40 | I9: 43 | J9: 39 | K9: =(H9+I9)/2 -> 41.5 | N9: Standard Error | O9: =_xlfn.STDEV.S(K2:K1001)/SQRT(COUNT(K2:K1001)) -> 0.44863195
A10: male | B10: group D | C10: high school | D10: free/reduced | E10: completed | F10: 17.875483755238896 | G10: 21 | H10: 64 | I10: 64 | J10: 67 | K10: =(H10+I10)/2 -> 64 | N10: t-stat | O10: =(AVERAGE(K2:K1001)-70)/(_xlfn.STDEV.S(K2:K1001)/SQRT(1000)) -> -5.2849557
A11: female | B11: group B | C11: high school | D11: free/reduced | E11: none | F11: 17.248682602823138 | G11: 26 | H11: 38 | I11: 60 | J11: 50 | K11: =(H11+I11)/2 -> 49
A12: male | B12: group C | C12: associate's degree | D12: standard | E12: none | F12: 18.487086923876006 | G12: 0 | H12: 58 | I12: 54 | J12: 52 | K12: =(H12+I12)/2 -> 56
A13: male | B13: group D | C13: associate's degree | D13: standard | E13: none | F13: 4.999179624789911 | G13: 26 | H13: 40 | I13: 52 | J13: 43 | K13: =(H13+I13)/2 -> 46
A14: female | B14: group B | C14: high school | D14: standard | E14: none | F14: 13.239396789012684 | G14: 14 | H14: 65 | I14: 81 | J14: 73 | K14: =(H14+I14)/2 -> 73 | N14: Row Labels | O14: Count of parental level of education
A15: male | B15: group A | C15: some college | D15: standard | E15: completed | F15: 5.7251807076636645 | G15: 1 | H15: 78 | I15: 72 | J15: 70 | K15: =(H15+I15)/2 -> 75 | N15: associate's degree | O15: 222
A16: female | B16: group A | C16: master's degree | D16: standard | E16: none | F16: 9.896569132428404 | G16: 27 | H16: 50 | I16: 53 | J16: 58 | K16: =(H16+I16)/2 -> 51.5 | N16: bachelor's degree | O16: 118
A17: female | B17: group C | C17: some high school | D17: standard | E17: none | F17: 10.779617489002412 | G17: 1 | H17: 69 | I17: 75 | J17: 78 | K17: =(H17+I17)/2 -> 72 | N17: high school | O17: 196
A18: male | B18: group C | C18: high school | D18: standard | E18: none | F18: 6.023180395708907 | G18: 17 | H18: 88 | I18: 89 | J18: 86 | K18: =(H18+I18)/2 -> 88.5 | N18: master's degree | O18: 59
A19: female | B19: group B | C19: some high school | D19: free/reduced | E19: none | F19: 8.412604737576387 | G19: 16 | H19: 18 | I19: 32 | J19: 28 | K19: =(H19+I19)/2 -> 25 | N19: some college | O19: 225
A20: male | B20: group C | C20: master's degree | D20: free/reduced | E20: completed | F20: 17.700306490945174 | G20: 16 | H20: 46 | I20: 42 | J20: 46 | K20: =(H20+I20)/2 -> 44 | N20: some high school | O20: 179
A21: female | B21: group C | C21: associate's degree | D21: free/reduced | E21: none | F21: 14.089872728233694 | G21: 3 | H21: 54 | I21: 58 | J21: 61 | K21: =(H21+I21)/2 -> 56 | N21: Grand Total | O21: 999
A22: male | B22: group D | C22: high school | D22: standard | E22: none | F22: 8.269315334203203 | G22: 29 | H22: 66 | I22: 69 | J22: 63 | K22: =(H22+I22)/2 -> 67.5
A23: female | B23: group B | C23: some college | D23: free/reduced | E23: completed | F23: 11.695136166746094 | G23: 15 | H23: 65 | I23: 75 | J23: 70 | K23: =(H23+I23)/2 -> 70
A24: male | B24: group D | C24: some college | D24: standard | E24: none | F24: 12.941403325177479 | G24: 9 | H24: 44 | I24: 54 | J24: 53 | K24: =(H24+I24)/2 -> 49 | X24: =SLOPE(J2:J1001,G2:G1001) -> 0.024228546
A25: female | B25: group C | C25: some high school | D25: standard | E25: none | F25: 14.63410545446303 | G25: 9 | H25: 69 | I25: 73 | J25: 73 | K25: =(H25+I25)/2 -> 71 | X25: =INTERCEPT(J2:J1001,G2:G1001) -> 67.702323
A26: male | B26: group D | C26: bachelor's degree | D26: free/reduced | E26: completed | F26: 8.045893561526373 | G26: 17 | H26: 74 | I26: 71 | J26: 80 | K26: =(H26+I26)/2 -> 72.5
A27: male | B27: group A | C27: master's degree | D27: free/reduced | E27: none | F27: 0.1069797738844569 | G27: 5 | H27: 73 | I27: 74 | J27: 72 | K27: =(H27+I27)/2 -> 73.5
A28: male | B28: group B | C28: some college | D28: standard | E28: none | F28: 8.528121129839457 | G28: 27 | H28: 69 | I28: 54 | J28: 55 | K28: =(H28+I28)/2 -> 61.5
A29: female | B29: group C | C29: bachelor's degree | D29: standard | E29: none | F29: 6.4107233361299105 | G29: 2 | H29: 67 | I29: 69 | J29: 75 | K29: =(H29+I29)/2 -> 68
A30: male | B30: group C | C30: high school | D30: standard | E30: none | F30: 13.591036731453679 | G30: 3 | H30: 70 | I30: 70 | J30: 65 | K30: =(H30+I30)/2 -> 70
A31: female | B31: group D | C31: master's degree | D31: standard | E31: none | F31: 16.12193495921495 | G31: 29 | H31: 62 | I31: 70 | J31: 75 | K31: =(H31+I31)/2 -> 66
A32: female | B32: group D | C32: some college | D32: standard | E32: none | F32: 8.368989943509161 | G32: 1 | H32: 69 | I32: 74 | J32: 74 | K32: =(H32+I32)/2 -> 71.5
A33: female | B33: group B | C33: some college | D33: standard | E33: none | F33: 11.41329157961578 | G33: 0 | H33: 63 | I33: 65 | J33: 61 | K33: =(H33+I33)/2 -> 64
A34: female | B34: group E | C34: master's degree | D34: free/reduced | E34: none | F34: 7.005447413386552 | G34: 4 | H34: 56 | I34: 72 | J34: 65 | K34: =(H34+I34)/2 -> 64
A35: male | B35: group D | C35: some college | D35: standard | E35: none | F35: 6.195306282858068 | G35: 7 | H35: 40 | I35: 42 | J35: 38 | K35: =(H35+I35)/2 -> 41
A36: male | B36: group E | C36: some college | D36: standard | E36: none | F36: 5.564343741376443 | G36: 19 | H36: 97 | I36: 87 | J36: 82 | K36: =(H36+I36)/2 -> 92
A37: male | B37: group E | C37: associate's degree | D37: standard | E37: completed | F37: 11.448154519355302 | G37: 19 | H37: 81 | I37: 81 | J37: 79 | K37: =(H37+I37)/2 -> 81
A38: female | B38: group D | C38: associate's degree | D38: standard | E38: none | F38: 19.916047355598373 | G38: 1 | H38: 74 | I38: 81 | J38: 83 | K38: =(H38+I38)/2 -> 77.5
A39: female | B39: group D | C39: some high school | D39: free/reduced | E39: none | F39: 18.981592063656336 | G39: 20 | H39: 50 | I39: 64 | J39: 59 | K39: =(H39+I39)/2 -> 57 | N39: Row Labels | O39: Count of lunch
A40: female | B40: group D | C40: associate's degree | D40: free/reduced | E40: completed | F40: 10.403614731335193 | G40: 20 | H40: 75 | I40: 90 | J40: 88 | K40: =(H40+I40)/2 -> 82.5 | N40: free/reduced | O40: 354
...

Sheet Math Scores Descriptive Stats
A1: Math Score | C1: Table 1
A3: Mean | B3: 66.089
A4: Standard Error | B4: 0.47949869
A5: Median | B5: 66
A6: Mode | B6: 65
A7: Standard Deviation | B7: 15.16308
A8: Sample Variance | B8: 229.919 | D8: Margin Of Error | F8: =_xlfn.CONFIDENCE.NORM(0.05,B7,B15) -> 0.93980017
A9: Kurtosis | B9: 0.27496406 | D9: Confidence Interval | F9: =B3-F8 -> 65.1492 | G9: =B3+F8 -> 67.0288
A10: Skewness | B10: -0.27893515
A11: Range | B11: 100 | D11: We are 95% confident that the sample mean is between (65.14919983,67.0288).
A12: Minimum | B12: 0
A13: Maximum | B13: 100
A14: Sum | B14: 66089
A15: Count | B15: 1000
A17: Minimum | B17: =MIN('Math Scores Descriptive Stats'!H2:H1001) -> 0
A18: 1st Quartile | B18: =_xlfn.QUARTILE.INC('Data Set'!H2:H1001,1) -> 57
A19: Median | B19: =B5 -> 66
A20: 3rd Quartile | B20: =_xlfn.QUARTILE.INC('Data Set'!H4:H1003,3) -> 77
A21: Maximum | B21: =B13 -> 100

Sheet Reading Scores Descriptive Stat
A1: Reading Score | C1: Table 2
A3: Mean | B3: 69.169
A4: Standard Error | B4: 0.46169861
A5: Median | B5: 70
A6: Mode | B6: 72
A7: Standard Deviation | B7: 14.600192
A8: Sample Variance | B8: 213.1656 | D8: Margin Of Error | F8: =_xlfn.CONFIDENCE.NORM(0.05,B7,B15) -> 0.90491264
A9: Kurtosis | B9: -0.068265459 | D9: Confidence Interval | F9: =B3-F8 -> 68.264087 | G9: =B3+F8 -> 70.073913
A10: Skewness | B10: -0.25910452
A11: Range | B11: 83 | D11: We are 95% confident that the sample mean is between (68.26408736,70.07391264).
A12: Minimum | B12: 17
A13: Maximum | B13: 100
A14: Sum | B14: 69169
A15: Count | B15: 1000
A17: Minimum | B17: =B12 -> 17
A18: 1st Quartile | B18: =_xlfn.QUARTILE.INC('Data Set'!I2:I1001,1) -> 59
A19: Median | B19: =B5 -> 70
A20: 3rd Quartile | B20: =_xlfn.QUARTILE.INC('Data Set'!I4:I1003,3) -> 79
A21: Maximum | B21: =B13 -> 100

Sheet Regression Model
A1: SUMMARY OUTPUT
A3: Regression Statistics
A4: Multiple R | B4: 0.013531122
A5: R Square | B5: 0.00018309127
A6: Adjusted R Square | B6: -0.00081872928
A7: Standard Error | B7: 15.201876
A8: Observations | B8: 1000
A10: ANOVA
B11: df | C11: SS | D11: MS | E11: F | F11: Significance F
A12: Regression | B12: 1 | C12: 42.23496 | D12: 42.23496 | E12: 0.18275855 | F12: 0.66910545
A13: Residual | B13: 998 | C13: 230634.85 | D13: 231.09704
A14: Total | B14: 999 | C14: 230677.08
B16: Coefficients | C16: Standard Error | D16: t Stat | E16: P-value | F16: Lower 95% | G16: Upper 95% | H16: Lower 95.0% | I16: Upper 95.0%
A17: Intercept | B17: 67.702323 | C17: 0.95279604 | D17: 71.056469 | E17: 0 | F17: 65.832609 | G17: 69.572036 | H17: 65.832609 | I17: 69.572036
A18: X Variable 1 | B18: 0.024228546 | C18: 0.056674606 | D18: 0.42750269 | E18: 0.66910545 | F18: -0.086986518 | G18: 0.13544361 | H18: -0.086986518 | I18: 0.13544361

Sheet Pivot Table
A1: parental level of education | B1: All
A2: lunch | B2: All
A3: test preparation course | B3: All
A5: Row Labels | B5: Sum of math score | C5: Sum of writing score | D5: Sum of reading score
A6: group A
A7: female | B7: 2107 | C7: 2443 | D7: 2484
A8: male | B8: 3378 | C8: 3135 | D8: 3272
A9: group B
A10: female | B10: 6386 | C10: 7285 | D10: 7392
A11: male | B11: 5670 | C11: 5179 | D11: 5405
A12: group C
A13: female | B13: 11166 | C13: 12920 | D13: 12950
A14: male | B14: 9398 | C14: 8717 | D14: 9094
A15: group D
A16: female | B16: 8417 | C16: 9678 | D16: 9552
A17: male | B17: 9232 | C17: 8700 | D17: 8796
A18: group E
A19: female | B19: 4886 | C19: 5212 | D19: 5233
A20: male | B20: 5449 | C20: 4785 | D20: 4991
A21: Grand Total | B21: 66089 | C21: 68054 | D21: 69169
